---
title: Try... Detectar... Finally (instrucción)
description: Aprenda a usar el control de excepciones con Visual Basic instrucciones try/catch/finally.
ms.date: 12/07/2018
f1_keywords:
- vb.Try...Catch...Finally
- vb.when
- vb.Finally
- vb.Catch
- vb.Try
helpviewer_keywords:
- Try...Catch...Finally statements
- Try statement [Visual Basic]
- try-catch exception handling, Try...Catch...Finally statements
- error handling, while running code
- Try statement [Visual Basic], Try...Catch...Finally
- Finally keyword [Visual Basic], Try...Catch...Finally
- Catch statement [Visual Basic]
- When keyword [Visual Basic]
- Visual Basic code, handling errors while running
- structured exception handling, Try...Catch...Finally statements
ms.assetid: d6488026-ccb3-42b8-a810-0d97b9d6472b
ms.openlocfilehash: 22f1611786a3da512632b5b547b7ef141c8f65c6
ms.sourcegitcommit: f8c270376ed905f6a8896ce0fe25b4f4b38ff498
ms.translationtype: MT
ms.contentlocale: es-ES
ms.lasthandoff: 06/04/2020
ms.locfileid: "84391773"
---
# <a name="trycatchfinally-statement-visual-basic"></a><span data-ttu-id="c9a13-103">Instrucción Try...Catch...Finally (Visual Basic)</span><span class="sxs-lookup"><span data-stu-id="c9a13-103">Try...Catch...Finally Statement (Visual Basic)</span></span>

<span data-ttu-id="c9a13-104">Proporciona una manera de controlar algunos o todos los errores posibles que se pueden producir en un bloque de código determinado, mientras se sigue ejecutando el código.</span><span class="sxs-lookup"><span data-stu-id="c9a13-104">Provides a way to handle some or all possible errors that may occur in a given block of code, while still running code.</span></span>

## <a name="syntax"></a><span data-ttu-id="c9a13-105">Sintaxis</span><span class="sxs-lookup"><span data-stu-id="c9a13-105">Syntax</span></span>

```vb
Try
    [ tryStatements ]
    [ Exit Try ]
[ Catch [ exception [ As type ] ] [ When expression ]
    [ catchStatements ]
    [ Exit Try ] ]
[ Catch ... ]
[ Finally
    [ finallyStatements ] ]
End Try
```

## <a name="parts"></a><span data-ttu-id="c9a13-106">Partes</span><span class="sxs-lookup"><span data-stu-id="c9a13-106">Parts</span></span>

|<span data-ttu-id="c9a13-107">Término</span><span class="sxs-lookup"><span data-stu-id="c9a13-107">Term</span></span>|<span data-ttu-id="c9a13-108">Definición</span><span class="sxs-lookup"><span data-stu-id="c9a13-108">Definition</span></span>|
|---|---|
|`tryStatements`|<span data-ttu-id="c9a13-109">Opcional.</span><span class="sxs-lookup"><span data-stu-id="c9a13-109">Optional.</span></span> <span data-ttu-id="c9a13-110">Instrucciones en las que se puede producir un error.</span><span class="sxs-lookup"><span data-stu-id="c9a13-110">Statement(s) where an error can occur.</span></span> <span data-ttu-id="c9a13-111">Puede ser una instrucción compuesta.</span><span class="sxs-lookup"><span data-stu-id="c9a13-111">Can be a compound statement.</span></span>|
|`Catch`|<span data-ttu-id="c9a13-112">Opcional.</span><span class="sxs-lookup"><span data-stu-id="c9a13-112">Optional.</span></span> <span data-ttu-id="c9a13-113">Se `Catch` permiten varios bloques.</span><span class="sxs-lookup"><span data-stu-id="c9a13-113">Multiple `Catch` blocks permitted.</span></span> <span data-ttu-id="c9a13-114">Si se produce una excepción al procesar el `Try` bloque, cada `Catch` instrucción se examina en orden textual para determinar si controla la excepción, con `exception` lo que representa la excepción que se ha producido.</span><span class="sxs-lookup"><span data-stu-id="c9a13-114">If an exception occurs when processing the `Try` block, each `Catch` statement is examined in textual order to determine whether it handles the exception, with `exception` representing the exception that has been thrown.</span></span>|
|`exception`|<span data-ttu-id="c9a13-115">Opcional.</span><span class="sxs-lookup"><span data-stu-id="c9a13-115">Optional.</span></span> <span data-ttu-id="c9a13-116">Cualquier nombre de variable.</span><span class="sxs-lookup"><span data-stu-id="c9a13-116">Any variable name.</span></span> <span data-ttu-id="c9a13-117">El valor inicial de `exception` es el valor del error producido.</span><span class="sxs-lookup"><span data-stu-id="c9a13-117">The initial value of `exception` is the value of the thrown error.</span></span> <span data-ttu-id="c9a13-118">Se utiliza con `Catch` para especificar el error detectado.</span><span class="sxs-lookup"><span data-stu-id="c9a13-118">Used with `Catch` to specify the error caught.</span></span> <span data-ttu-id="c9a13-119">Si se omite, la `Catch` instrucción detecta cualquier excepción.</span><span class="sxs-lookup"><span data-stu-id="c9a13-119">If omitted, the `Catch` statement catches any exception.</span></span>|
|`type`|<span data-ttu-id="c9a13-120">Opcional.</span><span class="sxs-lookup"><span data-stu-id="c9a13-120">Optional.</span></span> <span data-ttu-id="c9a13-121">Especifica el tipo de filtro de clase.</span><span class="sxs-lookup"><span data-stu-id="c9a13-121">Specifies the type of class filter.</span></span> <span data-ttu-id="c9a13-122">Si el valor de `exception` es del tipo especificado por `type` o de un tipo derivado, el identificador se enlaza al objeto de excepción.</span><span class="sxs-lookup"><span data-stu-id="c9a13-122">If the value of `exception` is of the type specified by `type` or of a derived type, the identifier becomes bound to the exception object.</span></span>|
|`When`|<span data-ttu-id="c9a13-123">Opcional.</span><span class="sxs-lookup"><span data-stu-id="c9a13-123">Optional.</span></span> <span data-ttu-id="c9a13-124">Una `Catch` instrucción con una `When` cláusula solo detecta las excepciones cuando `expression` se evalúa como `True` .</span><span class="sxs-lookup"><span data-stu-id="c9a13-124">A `Catch` statement with a `When` clause catches exceptions only when `expression` evaluates to `True`.</span></span> <span data-ttu-id="c9a13-125">Una `When` cláusula solo se aplica después de comprobar el tipo de la excepción y `expression` puede hacer referencia al identificador que representa la excepción.</span><span class="sxs-lookup"><span data-stu-id="c9a13-125">A `When` clause is applied only after checking the type of the exception, and `expression` may refer to the identifier representing the exception.</span></span>|
|`expression`|<span data-ttu-id="c9a13-126">Opcional.</span><span class="sxs-lookup"><span data-stu-id="c9a13-126">Optional.</span></span> <span data-ttu-id="c9a13-127">Se debe poder convertir implícitamente en `Boolean` .</span><span class="sxs-lookup"><span data-stu-id="c9a13-127">Must be implicitly convertible to `Boolean`.</span></span> <span data-ttu-id="c9a13-128">Cualquier expresión que describa un filtro genérico.</span><span class="sxs-lookup"><span data-stu-id="c9a13-128">Any expression that describes a generic filter.</span></span> <span data-ttu-id="c9a13-129">Normalmente se usa para filtrar por número de error.</span><span class="sxs-lookup"><span data-stu-id="c9a13-129">Typically used to filter by error number.</span></span> <span data-ttu-id="c9a13-130">Se utiliza con `When` la palabra clave para especificar las circunstancias en las que se detecta el error.</span><span class="sxs-lookup"><span data-stu-id="c9a13-130">Used with `When` keyword to specify circumstances under which the error is caught.</span></span>|
|`catchStatements`|<span data-ttu-id="c9a13-131">Opcional.</span><span class="sxs-lookup"><span data-stu-id="c9a13-131">Optional.</span></span> <span data-ttu-id="c9a13-132">Instrucciones para controlar los errores que se producen en el bloque asociado `Try` .</span><span class="sxs-lookup"><span data-stu-id="c9a13-132">Statement(s) to handle errors that occur in the associated `Try` block.</span></span> <span data-ttu-id="c9a13-133">Puede ser una instrucción compuesta.</span><span class="sxs-lookup"><span data-stu-id="c9a13-133">Can be a compound statement.</span></span>|
|`Exit Try`|<span data-ttu-id="c9a13-134">Opcional.</span><span class="sxs-lookup"><span data-stu-id="c9a13-134">Optional.</span></span> <span data-ttu-id="c9a13-135">Palabra clave que sale de la `Try...Catch...Finally` estructura.</span><span class="sxs-lookup"><span data-stu-id="c9a13-135">Keyword that breaks out of the `Try...Catch...Finally` structure.</span></span> <span data-ttu-id="c9a13-136">La ejecución se reanuda con el código inmediatamente después de la `End Try` instrucción.</span><span class="sxs-lookup"><span data-stu-id="c9a13-136">Execution resumes with the code immediately following the `End Try` statement.</span></span> <span data-ttu-id="c9a13-137">La `Finally` instrucción se seguirá ejecutando.</span><span class="sxs-lookup"><span data-stu-id="c9a13-137">The `Finally` statement will still be executed.</span></span> <span data-ttu-id="c9a13-138">No se permite en `Finally` bloques.</span><span class="sxs-lookup"><span data-stu-id="c9a13-138">Not allowed in `Finally` blocks.</span></span>|
|`Finally`|<span data-ttu-id="c9a13-139">Opcional.</span><span class="sxs-lookup"><span data-stu-id="c9a13-139">Optional.</span></span> <span data-ttu-id="c9a13-140">Un `Finally` bloque siempre se ejecuta cuando la ejecución deja parte de la `Try...Catch` instrucción.</span><span class="sxs-lookup"><span data-stu-id="c9a13-140">A `Finally` block is always executed when execution leaves any part of the `Try...Catch` statement.</span></span>|
|`finallyStatements`|<span data-ttu-id="c9a13-141">Opcional.</span><span class="sxs-lookup"><span data-stu-id="c9a13-141">Optional.</span></span> <span data-ttu-id="c9a13-142">Instrucciones que se ejecutan después de que se haya producido el otro procesamiento de errores.</span><span class="sxs-lookup"><span data-stu-id="c9a13-142">Statement(s) that are executed after all other error processing has occurred.</span></span>|
|`End Try`|<span data-ttu-id="c9a13-143">Finaliza la `Try...Catch...Finally` estructura.</span><span class="sxs-lookup"><span data-stu-id="c9a13-143">Terminates the `Try...Catch...Finally` structure.</span></span>|

## <a name="remarks"></a><span data-ttu-id="c9a13-144">Observaciones</span><span class="sxs-lookup"><span data-stu-id="c9a13-144">Remarks</span></span>

<span data-ttu-id="c9a13-145">Si espera que se produzca una excepción determinada durante una sección de código determinada, coloque el código en un `Try` bloque y use un `Catch` bloque para conservar el control y controle la excepción si se produce.</span><span class="sxs-lookup"><span data-stu-id="c9a13-145">If you expect that a particular exception might occur during a particular section of code, put the code in a `Try` block and use a `Catch` block to retain control and handle the exception if it occurs.</span></span>

<span data-ttu-id="c9a13-146">Una `Try…Catch` instrucción consta de un `Try` bloque seguido de una o más `Catch` cláusulas, que especifican Controladores para distintas excepciones.</span><span class="sxs-lookup"><span data-stu-id="c9a13-146">A `Try…Catch` statement consists of a `Try` block followed by one or more `Catch` clauses, which specify handlers for various exceptions.</span></span> <span data-ttu-id="c9a13-147">Cuando se produce una excepción en un `Try` bloque, Visual Basic busca la `Catch` instrucción que controla la excepción.</span><span class="sxs-lookup"><span data-stu-id="c9a13-147">When an exception is thrown in a `Try` block, Visual Basic looks for the `Catch` statement that handles the exception.</span></span> <span data-ttu-id="c9a13-148">Si `Catch` no se encuentra una instrucción coincidente, Visual Basic examina el método que llamó al método actual, y así sucesivamente en la pila de llamadas.</span><span class="sxs-lookup"><span data-stu-id="c9a13-148">If a matching `Catch` statement is not found, Visual Basic examines the method that called the current method, and so on up the call stack.</span></span> <span data-ttu-id="c9a13-149">Si no `Catch` se encuentra ningún bloque, Visual Basic muestra al usuario un mensaje de excepción no controlada y detiene la ejecución del programa.</span><span class="sxs-lookup"><span data-stu-id="c9a13-149">If no `Catch` block is found, Visual Basic displays an unhandled exception message to the user and stops execution of the program.</span></span>

<span data-ttu-id="c9a13-150">Puede usar más de una `Catch` instrucción en una `Try…Catch` instrucción.</span><span class="sxs-lookup"><span data-stu-id="c9a13-150">You can use more than one `Catch` statement in a `Try…Catch` statement.</span></span> <span data-ttu-id="c9a13-151">Si lo hace, el orden de las `Catch` cláusulas es importante porque se examinan en orden.</span><span class="sxs-lookup"><span data-stu-id="c9a13-151">If you do this, the order of the `Catch` clauses is significant because they are examined in order.</span></span> <span data-ttu-id="c9a13-152">Detectar las excepciones más específicas antes que las menos específicas.</span><span class="sxs-lookup"><span data-stu-id="c9a13-152">Catch the more specific exceptions before the less specific ones.</span></span>

<span data-ttu-id="c9a13-153">Las siguientes `Catch` condiciones de instrucción son las menos específicas y detectarán todas las excepciones que derivan de la <xref:System.Exception> clase.</span><span class="sxs-lookup"><span data-stu-id="c9a13-153">The following `Catch` statement conditions are the least specific, and will catch all exceptions that derive from the <xref:System.Exception> class.</span></span> <span data-ttu-id="c9a13-154">Normalmente, debe usar una de estas variaciones como el último `Catch` bloque de la `Try...Catch...Finally` estructura, después de detectar todas las excepciones específicas que espera.</span><span class="sxs-lookup"><span data-stu-id="c9a13-154">You should ordinarily use one of these variations as the last `Catch` block in the `Try...Catch...Finally` structure, after catching all the specific exceptions you expect.</span></span> <span data-ttu-id="c9a13-155">El flujo de control no puede llegar nunca a un `Catch` bloque que siga cualquiera de estas variaciones.</span><span class="sxs-lookup"><span data-stu-id="c9a13-155">Control flow can never reach a `Catch` block that follows either of these variations.</span></span>

- <span data-ttu-id="c9a13-156">El `type` es `Exception` , por ejemplo:`Catch ex As Exception`</span><span class="sxs-lookup"><span data-stu-id="c9a13-156">The `type` is `Exception`, for example: `Catch ex As Exception`</span></span>

- <span data-ttu-id="c9a13-157">La instrucción no tiene ninguna `exception` variable, por ejemplo:`Catch`</span><span class="sxs-lookup"><span data-stu-id="c9a13-157">The statement has no `exception` variable, for example: `Catch`</span></span>

<span data-ttu-id="c9a13-158">Cuando una `Try…Catch…Finally` instrucción está anidada en otro `Try` bloque, Visual Basic examina primero cada `Catch` instrucción en el bloque más interno `Try` .</span><span class="sxs-lookup"><span data-stu-id="c9a13-158">When a `Try…Catch…Finally` statement is nested in another `Try` block, Visual Basic first examines each `Catch` statement in the innermost `Try` block.</span></span> <span data-ttu-id="c9a13-159">Si no `Catch` se encuentra ninguna instrucción coincidente, la búsqueda continúa con las `Catch` instrucciones del bloque exterior `Try…Catch…Finally` .</span><span class="sxs-lookup"><span data-stu-id="c9a13-159">If no matching `Catch` statement is found, the search proceeds to the `Catch` statements of the outer `Try…Catch…Finally` block.</span></span>

<span data-ttu-id="c9a13-160">Las variables locales de un `Try` bloque no están disponibles en un `Catch` bloque porque son bloques independientes.</span><span class="sxs-lookup"><span data-stu-id="c9a13-160">Local variables from a `Try` block are not available in a `Catch` block because they are separate blocks.</span></span> <span data-ttu-id="c9a13-161">Si desea utilizar una variable en más de un bloque, declare la variable fuera de la `Try...Catch...Finally` estructura.</span><span class="sxs-lookup"><span data-stu-id="c9a13-161">If you want to use a variable in more than one block, declare the variable outside the `Try...Catch...Finally` structure.</span></span>

> [!TIP]
> <span data-ttu-id="c9a13-162">La `Try…Catch…Finally` instrucción está disponible como fragmento de código de IntelliSense.</span><span class="sxs-lookup"><span data-stu-id="c9a13-162">The `Try…Catch…Finally` statement is available as an IntelliSense code snippet.</span></span> <span data-ttu-id="c9a13-163">En el administrador de fragmentos de código, expanda **patrones de código: Si, para cada uno, pruebe Catch, Property, etc**. y, a continuación, **control de errores (excepciones)**.</span><span class="sxs-lookup"><span data-stu-id="c9a13-163">In the Code Snippets Manager, expand **Code Patterns - If, For Each, Try Catch, Property, etc**, and then **Error Handling (Exceptions)**.</span></span> <span data-ttu-id="c9a13-164">Para obtener más información, vea [Fragmentos de código](/visualstudio/ide/code-snippets).</span><span class="sxs-lookup"><span data-stu-id="c9a13-164">For more information, see [Code Snippets](/visualstudio/ide/code-snippets).</span></span>

## <a name="finally-block"></a><span data-ttu-id="c9a13-165">Bloque Finally</span><span class="sxs-lookup"><span data-stu-id="c9a13-165">Finally block</span></span>

<span data-ttu-id="c9a13-166">Si tiene una o más instrucciones que se deben ejecutar antes de salir de la `Try` estructura, utilice un `Finally` bloque.</span><span class="sxs-lookup"><span data-stu-id="c9a13-166">If you have one or more statements that must run before you exit the `Try` structure, use a `Finally` block.</span></span> <span data-ttu-id="c9a13-167">El control pasa al `Finally` bloque justo antes de salir de la `Try…Catch` estructura.</span><span class="sxs-lookup"><span data-stu-id="c9a13-167">Control passes to the `Finally` block just before it passes out of the `Try…Catch` structure.</span></span> <span data-ttu-id="c9a13-168">Esto es así incluso si se produce una excepción en cualquier parte dentro de la `Try` estructura.</span><span class="sxs-lookup"><span data-stu-id="c9a13-168">This is true even if an exception occurs anywhere inside the `Try` structure.</span></span>

<span data-ttu-id="c9a13-169">Un `Finally` bloque es útil para ejecutar cualquier código que deba ejecutarse incluso si se produce una excepción.</span><span class="sxs-lookup"><span data-stu-id="c9a13-169">A `Finally` block is useful for running any code that must execute even if there is an exception.</span></span> <span data-ttu-id="c9a13-170">El control se pasa al `Finally` bloque independientemente de cómo `Try...Catch` salga el bloque.</span><span class="sxs-lookup"><span data-stu-id="c9a13-170">Control is passed to the `Finally` block regardless of how the `Try...Catch` block exits.</span></span>

<span data-ttu-id="c9a13-171">El código de un `Finally` bloque se ejecuta incluso si el código encuentra una `Return` instrucción en un `Try` bloque o `Catch` .</span><span class="sxs-lookup"><span data-stu-id="c9a13-171">The code in a `Finally` block runs even if your code encounters a `Return` statement in a `Try` or `Catch` block.</span></span> <span data-ttu-id="c9a13-172">El control no pasa de un `Try` `Catch` bloque o al bloque correspondiente `Finally` en los casos siguientes:</span><span class="sxs-lookup"><span data-stu-id="c9a13-172">Control does not pass from a `Try` or `Catch` block to the corresponding `Finally` block in the following cases:</span></span>

- <span data-ttu-id="c9a13-173">Se encuentra una [instrucción end](end-statement.md) en el `Try` `Catch` bloque o.</span><span class="sxs-lookup"><span data-stu-id="c9a13-173">An [End Statement](end-statement.md) is encountered in the `Try` or `Catch` block.</span></span>

- <span data-ttu-id="c9a13-174"><xref:System.StackOverflowException>Se produce una excepción en `Try` el `Catch` bloque o.</span><span class="sxs-lookup"><span data-stu-id="c9a13-174">A <xref:System.StackOverflowException> is thrown in the `Try` or `Catch` block.</span></span>

<span data-ttu-id="c9a13-175">No es válido transferir explícitamente la ejecución a un `Finally` bloque.</span><span class="sxs-lookup"><span data-stu-id="c9a13-175">It is not valid to explicitly transfer execution into a `Finally` block.</span></span> <span data-ttu-id="c9a13-176">La transferencia de la ejecución fuera de un `Finally` bloque no es válida, excepto a través de una excepción.</span><span class="sxs-lookup"><span data-stu-id="c9a13-176">Transferring execution out of a `Finally` block is not valid, except through an exception.</span></span>

<span data-ttu-id="c9a13-177">Si una `Try` instrucción no contiene al menos un `Catch` bloque, debe contener un `Finally` bloque.</span><span class="sxs-lookup"><span data-stu-id="c9a13-177">If a `Try` statement does not contain at least one `Catch` block, it must contain a `Finally` block.</span></span>

> [!TIP]
> <span data-ttu-id="c9a13-178">Si no tiene que detectar excepciones específicas, la `Using` instrucción se comporta como un `Try…Finally` bloque y garantiza la eliminación de los recursos, independientemente de cómo salga del bloque.</span><span class="sxs-lookup"><span data-stu-id="c9a13-178">If you do not have to catch specific exceptions, the `Using` statement behaves like a `Try…Finally` block, and guarantees disposal of the resources, regardless of how you exit the block.</span></span> <span data-ttu-id="c9a13-179">Esto es así incluso con una excepción no controlada.</span><span class="sxs-lookup"><span data-stu-id="c9a13-179">This is true even with an unhandled exception.</span></span> <span data-ttu-id="c9a13-180">Para obtener más información, vea [using (instrucción](using-statement.md)).</span><span class="sxs-lookup"><span data-stu-id="c9a13-180">For more information, see [Using Statement](using-statement.md).</span></span>

## <a name="exception-argument"></a><span data-ttu-id="c9a13-181">Argumento de excepción</span><span class="sxs-lookup"><span data-stu-id="c9a13-181">Exception argument</span></span>

<span data-ttu-id="c9a13-182">El `Catch` `exception` argumento de bloque es una instancia de la <xref:System.Exception> clase o una clase que deriva de la `Exception` clase.</span><span class="sxs-lookup"><span data-stu-id="c9a13-182">The `Catch` block `exception` argument is an instance of the <xref:System.Exception> class or a class that derives from the `Exception` class.</span></span> <span data-ttu-id="c9a13-183">La `Exception` instancia de clase se corresponde con el error que se produjo en el `Try` bloque.</span><span class="sxs-lookup"><span data-stu-id="c9a13-183">The `Exception` class instance corresponds to the error that occurred in the `Try` block.</span></span>

<span data-ttu-id="c9a13-184">Las propiedades del `Exception` objeto ayudan a identificar la causa y la ubicación de una excepción.</span><span class="sxs-lookup"><span data-stu-id="c9a13-184">The properties of the `Exception` object help to identify the cause and location of an exception.</span></span> <span data-ttu-id="c9a13-185">Por ejemplo, la <xref:System.Exception.StackTrace%2A> propiedad enumera los métodos a los que se ha provocado la excepción, lo que le ayuda a encontrar el lugar en el que se produjo el error en el código.</span><span class="sxs-lookup"><span data-stu-id="c9a13-185">For example, the <xref:System.Exception.StackTrace%2A> property lists the called methods that led to the exception, helping you find where the error occurred in the code.</span></span> <span data-ttu-id="c9a13-186"><xref:System.Exception.Message%2A>Devuelve un mensaje que describe la excepción.</span><span class="sxs-lookup"><span data-stu-id="c9a13-186"><xref:System.Exception.Message%2A> returns a message that describes the exception.</span></span> <span data-ttu-id="c9a13-187"><xref:System.Exception.HelpLink%2A>Devuelve un vínculo a un archivo de ayuda asociado.</span><span class="sxs-lookup"><span data-stu-id="c9a13-187"><xref:System.Exception.HelpLink%2A> returns a link to an associated Help file.</span></span> <span data-ttu-id="c9a13-188"><xref:System.Exception.InnerException%2A>Devuelve el `Exception` objeto que causó la excepción actual, o devuelve si no hay `Nothing` ningún original `Exception` .</span><span class="sxs-lookup"><span data-stu-id="c9a13-188"><xref:System.Exception.InnerException%2A> returns the `Exception` object that caused the current exception, or it returns `Nothing` if there is no original `Exception`.</span></span>

## <a name="considerations-when-using-a-trycatch-statement"></a><span data-ttu-id="c9a13-189">Consideraciones al usar una instrucción try... Catch (instrucción)</span><span class="sxs-lookup"><span data-stu-id="c9a13-189">Considerations when using a Try…Catch statement</span></span>

<span data-ttu-id="c9a13-190">Use una `Try…Catch` instrucción solo para indicar la aparición de eventos de programa inusuales o imprevistos.</span><span class="sxs-lookup"><span data-stu-id="c9a13-190">Use a `Try…Catch` statement only to signal the occurrence of unusual or unanticipated program events.</span></span> <span data-ttu-id="c9a13-191">Entre los motivos se incluyen los siguientes:</span><span class="sxs-lookup"><span data-stu-id="c9a13-191">Reasons for this include the following:</span></span>

- <span data-ttu-id="c9a13-192">La detección de excepciones en tiempo de ejecución crea una sobrecarga adicional y es probable que sea más lenta que la comprobación previa para evitar excepciones.</span><span class="sxs-lookup"><span data-stu-id="c9a13-192">Catching exceptions at runtime creates additional overhead, and is likely to be slower than pre-checking to avoid exceptions.</span></span>

- <span data-ttu-id="c9a13-193">Si un `Catch` bloque no se controla correctamente, es posible que la excepción no se notifique correctamente a los usuarios.</span><span class="sxs-lookup"><span data-stu-id="c9a13-193">If a `Catch` block is not handled correctly, the exception might not be reported correctly to users.</span></span>

- <span data-ttu-id="c9a13-194">El control de excepciones hace que un programa sea más complejo.</span><span class="sxs-lookup"><span data-stu-id="c9a13-194">Exception handling makes a program more complex.</span></span>

<span data-ttu-id="c9a13-195">No siempre se necesita una `Try…Catch` instrucción para comprobar si hay una condición que es probable que se produzca.</span><span class="sxs-lookup"><span data-stu-id="c9a13-195">You do not always need a `Try…Catch` statement to check for a condition that is likely to occur.</span></span> <span data-ttu-id="c9a13-196">En el ejemplo siguiente se comprueba si existe un archivo antes de intentar abrirlo.</span><span class="sxs-lookup"><span data-stu-id="c9a13-196">The following example checks whether a file exists before trying to open it.</span></span> <span data-ttu-id="c9a13-197">Esto reduce la necesidad de detectar una excepción producida por el <xref:System.IO.File.OpenText%2A> método.</span><span class="sxs-lookup"><span data-stu-id="c9a13-197">This reduces the need for catching an exception thrown by the <xref:System.IO.File.OpenText%2A> method.</span></span>

[!code-vb[VbVbalrStatements#94](~/samples/snippets/visualbasic/VS_Snippets_VBCSharp/VbVbalrStatements/VB/Class1.vb#94)]

<span data-ttu-id="c9a13-198">Asegúrese de que el código de `Catch` los bloques pueda notificar correctamente las excepciones a los usuarios, ya sea a través de registros seguros para subprocesos o mensajes adecuados.</span><span class="sxs-lookup"><span data-stu-id="c9a13-198">Ensure that code in `Catch` blocks can properly report exceptions to users, whether through thread-safe logging or appropriate messages.</span></span> <span data-ttu-id="c9a13-199">De lo contrario, es posible que las excepciones sigan siendo desconocidas.</span><span class="sxs-lookup"><span data-stu-id="c9a13-199">Otherwise, exceptions might remain unknown.</span></span>

## <a name="async-methods"></a><span data-ttu-id="c9a13-200">Métodos asincrónicos</span><span class="sxs-lookup"><span data-stu-id="c9a13-200">Async methods</span></span>

<span data-ttu-id="c9a13-201">Si marca un método con el modificador [Async](../modifiers/async.md) , puede usar el operador [Await](../operators/await-operator.md) en el método.</span><span class="sxs-lookup"><span data-stu-id="c9a13-201">If you mark a method with the [Async](../modifiers/async.md) modifier, you can use the [Await](../operators/await-operator.md) operator in the method.</span></span> <span data-ttu-id="c9a13-202">Una instrucción con el `Await` operador suspende la ejecución del método hasta que se completa la tarea esperada.</span><span class="sxs-lookup"><span data-stu-id="c9a13-202">A statement with the `Await` operator suspends execution of the method until the awaited task completes.</span></span> <span data-ttu-id="c9a13-203">La tarea representa el trabajo en curso.</span><span class="sxs-lookup"><span data-stu-id="c9a13-203">The task represents ongoing work.</span></span> <span data-ttu-id="c9a13-204">Cuando finaliza la tarea asociada al `Await` operador, la ejecución se reanuda en el mismo método.</span><span class="sxs-lookup"><span data-stu-id="c9a13-204">When the task that's associated with the `Await` operator finishes, execution resumes in the same method.</span></span> <span data-ttu-id="c9a13-205">Para obtener más información, vea [flujo de control en programas Async](../../programming-guide/concepts/async/control-flow-in-async-programs.md).</span><span class="sxs-lookup"><span data-stu-id="c9a13-205">For more information, see [Control Flow in Async Programs](../../programming-guide/concepts/async/control-flow-in-async-programs.md).</span></span>

<span data-ttu-id="c9a13-206">Una tarea devuelta por un método asincrónico puede finalizar en un estado de error, lo que indica que se completó debido a una excepción no controlada.</span><span class="sxs-lookup"><span data-stu-id="c9a13-206">A task returned by an Async method may end in a faulted state, indicating that it completed due to an unhandled exception.</span></span> <span data-ttu-id="c9a13-207">Una tarea también puede terminar en un estado cancelado, lo que provoca que `OperationCanceledException` se produzca una excepción de la expresión Await.</span><span class="sxs-lookup"><span data-stu-id="c9a13-207">A task may also end in a canceled state, which results in an `OperationCanceledException` being thrown out of the await expression.</span></span> <span data-ttu-id="c9a13-208">Para detectar cualquier tipo de excepción, coloque la `Await` expresión que está asociada a la tarea en un `Try` bloque y Capture la excepción en el `Catch` bloque.</span><span class="sxs-lookup"><span data-stu-id="c9a13-208">To catch either type of exception, place the `Await` expression that's associated with the task in a `Try` block, and catch the exception in the `Catch` block.</span></span> <span data-ttu-id="c9a13-209">Más adelante en este tema se proporciona un ejemplo.</span><span class="sxs-lookup"><span data-stu-id="c9a13-209">An example is provided later in this topic.</span></span>

<span data-ttu-id="c9a13-210">Una tarea puede tener un estado de error porque varias excepciones eran responsables de su error.</span><span class="sxs-lookup"><span data-stu-id="c9a13-210">A task can be in a faulted state because multiple exceptions were responsible for its faulting.</span></span> <span data-ttu-id="c9a13-211">Por ejemplo, la tarea podría ser el resultado de una llamada a <xref:System.Threading.Tasks.Task.WhenAll%2A?displayProperty=nameWithType>.</span><span class="sxs-lookup"><span data-stu-id="c9a13-211">For example, the task might be the result of a call to <xref:System.Threading.Tasks.Task.WhenAll%2A?displayProperty=nameWithType>.</span></span> <span data-ttu-id="c9a13-212">Cuando espera una tarea de este tipo, la excepción detectada es solo una de las excepciones y no puede predecir qué excepción se detectará.</span><span class="sxs-lookup"><span data-stu-id="c9a13-212">When you await such a task, the caught exception is only one of the exceptions, and you can't predict which exception will be caught.</span></span> <span data-ttu-id="c9a13-213">Más adelante en este tema se proporciona un ejemplo.</span><span class="sxs-lookup"><span data-stu-id="c9a13-213">An example is provided later in this topic.</span></span>

<span data-ttu-id="c9a13-214">Una `Await` expresión no puede estar dentro de un `Catch` bloque o `Finally` bloque.</span><span class="sxs-lookup"><span data-stu-id="c9a13-214">An `Await` expression can't be inside a `Catch` block or `Finally` block.</span></span>

## <a name="iterators"></a><span data-ttu-id="c9a13-215">Iterators</span><span class="sxs-lookup"><span data-stu-id="c9a13-215">Iterators</span></span>

<span data-ttu-id="c9a13-216">Una función de iterador o un `Get` descriptor de acceso realiza una iteración personalizada en una colección.</span><span class="sxs-lookup"><span data-stu-id="c9a13-216">An iterator function or `Get` accessor performs a custom iteration over a collection.</span></span> <span data-ttu-id="c9a13-217">Un iterador usa una instrucción [yield](yield-statement.md) para devolver cada elemento de la colección de uno en uno.</span><span class="sxs-lookup"><span data-stu-id="c9a13-217">An iterator uses a [Yield](yield-statement.md) statement to return each element of the collection one at a time.</span></span> <span data-ttu-id="c9a13-218">Se llama a una función de iterador mediante un método [for each... Instrucción siguiente](for-each-next-statement.md).</span><span class="sxs-lookup"><span data-stu-id="c9a13-218">You call an iterator function by using a [For Each...Next Statement](for-each-next-statement.md).</span></span>

<span data-ttu-id="c9a13-219">Una `Yield` instrucción puede estar dentro de un `Try` bloque.</span><span class="sxs-lookup"><span data-stu-id="c9a13-219">A `Yield` statement can be inside a `Try` block.</span></span> <span data-ttu-id="c9a13-220">Un `Try` bloque que contiene una `Yield` instrucción puede tener `Catch` bloques y puede tener un `Finally` bloque.</span><span class="sxs-lookup"><span data-stu-id="c9a13-220">A `Try` block that contains a `Yield` statement can have `Catch` blocks, and can have a `Finally` block.</span></span> <span data-ttu-id="c9a13-221">Vea la sección "Try blocks in Visual Basic" de [iteradores](../../programming-guide/concepts/iterators.md) para obtener un ejemplo.</span><span class="sxs-lookup"><span data-stu-id="c9a13-221">See the "Try Blocks in Visual Basic" section of [Iterators](../../programming-guide/concepts/iterators.md) for an example.</span></span>

<span data-ttu-id="c9a13-222">Una `Yield` instrucción no puede estar dentro de un `Catch` bloque o un `Finally` bloque.</span><span class="sxs-lookup"><span data-stu-id="c9a13-222">A `Yield` statement cannot be inside a `Catch` block or a `Finally` block.</span></span>

<span data-ttu-id="c9a13-223">Si el `For Each` cuerpo (fuera de la función de iterador) produce una excepción, `Catch` no se ejecuta un bloque de la función de iterador, pero `Finally` se ejecuta un bloque en la función de iterador.</span><span class="sxs-lookup"><span data-stu-id="c9a13-223">If the `For Each` body (outside of the iterator function) throws an exception, a `Catch` block in the iterator function is not executed, but a `Finally` block in the iterator function is executed.</span></span> <span data-ttu-id="c9a13-224">Un `Catch` bloque dentro de una función de iterador solo detecta las excepciones que se producen dentro de la función de iterador.</span><span class="sxs-lookup"><span data-stu-id="c9a13-224">A `Catch` block inside an iterator function catches only exceptions that occur inside the iterator function.</span></span>

## <a name="partial-trust-situations"></a><span data-ttu-id="c9a13-225">Situaciones de confianza parcial</span><span class="sxs-lookup"><span data-stu-id="c9a13-225">Partial-trust situations</span></span>

<span data-ttu-id="c9a13-226">En situaciones de confianza parcial, como una aplicación hospedada en un recurso compartido de red, `Try...Catch...Finally` no detecta las excepciones de seguridad que se producen antes de que se invoque el método que contiene la llamada.</span><span class="sxs-lookup"><span data-stu-id="c9a13-226">In partial-trust situations, such as an application hosted on a network share, `Try...Catch...Finally` does not catch security exceptions that occur before the method that contains the call is invoked.</span></span> <span data-ttu-id="c9a13-227">En el ejemplo siguiente, cuando se coloca en un recurso compartido de servidor y se ejecuta desde allí, se genera el error "System. Security. SecurityException: error en la solicitud."</span><span class="sxs-lookup"><span data-stu-id="c9a13-227">The following example, when you put it on a server share and run from there, produces the error "System.Security.SecurityException: Request Failed."</span></span> <span data-ttu-id="c9a13-228">Para obtener más información sobre las excepciones de seguridad, vea la <xref:System.Security.SecurityException> clase.</span><span class="sxs-lookup"><span data-stu-id="c9a13-228">For more information about security exceptions, see the <xref:System.Security.SecurityException> class.</span></span>

[!code-vb[VbVbalrStatements#85](~/samples/snippets/visualbasic/VS_Snippets_VBCSharp/VbVbalrStatements/VB/Class1.vb#85)]

<span data-ttu-id="c9a13-229">En una situación de confianza parcial, debe colocar la `Process.Start` instrucción en un independiente `Sub` .</span><span class="sxs-lookup"><span data-stu-id="c9a13-229">In such a partial-trust situation, you have to put the `Process.Start` statement in a separate `Sub`.</span></span> <span data-ttu-id="c9a13-230">`Sub`Se producirá un error en la llamada inicial a.</span><span class="sxs-lookup"><span data-stu-id="c9a13-230">The initial call to the `Sub` will fail.</span></span> <span data-ttu-id="c9a13-231">Esto permite `Try...Catch` que se detecte antes de `Sub` que `Process.Start` se inicie el que contiene y se produzca la excepción de seguridad.</span><span class="sxs-lookup"><span data-stu-id="c9a13-231">This enables `Try...Catch` to catch it before the `Sub` that contains `Process.Start` is started and the security exception produced.</span></span>

## <a name="examples"></a><span data-ttu-id="c9a13-232">Ejemplos</span><span class="sxs-lookup"><span data-stu-id="c9a13-232">Examples</span></span>

### <a name="the-structure-of-trycatchfinally"></a><span data-ttu-id="c9a13-233">La estructura de try... Detectar... Terminar</span><span class="sxs-lookup"><span data-stu-id="c9a13-233">The structure of Try...Catch...Finally</span></span>

<span data-ttu-id="c9a13-234">En el ejemplo siguiente se muestra la estructura de la `Try...Catch...Finally` instrucción.</span><span class="sxs-lookup"><span data-stu-id="c9a13-234">The following example illustrates the structure of the `Try...Catch...Finally` statement.</span></span>

[!code-vb[VbVbalrStatements#86](~/samples/snippets/visualbasic/VS_Snippets_VBCSharp/VbVbalrStatements/VB/Class1.vb#86)]  

### <a name="exception-in-a-method-called-from-a-try-block"></a><span data-ttu-id="c9a13-235">Excepción en un método llamado desde un bloque try</span><span class="sxs-lookup"><span data-stu-id="c9a13-235">Exception in a method called from a Try block</span></span>

<span data-ttu-id="c9a13-236">En el ejemplo siguiente, el `CreateException` método produce una excepción `NullReferenceException` .</span><span class="sxs-lookup"><span data-stu-id="c9a13-236">In the following example, the `CreateException` method throws a `NullReferenceException`.</span></span> <span data-ttu-id="c9a13-237">El código que genera la excepción no está en un `Try` bloque.</span><span class="sxs-lookup"><span data-stu-id="c9a13-237">The code that generates the exception is not in a `Try` block.</span></span> <span data-ttu-id="c9a13-238">Por lo tanto, el `CreateException` método no controla la excepción.</span><span class="sxs-lookup"><span data-stu-id="c9a13-238">Therefore, the `CreateException` method does not handle the exception.</span></span> <span data-ttu-id="c9a13-239">El `RunSample` método controla la excepción porque la llamada al `CreateException` método está en un `Try` bloque.</span><span class="sxs-lookup"><span data-stu-id="c9a13-239">The `RunSample` method does handle the exception because the call to the `CreateException` method is in a `Try` block.</span></span>

<span data-ttu-id="c9a13-240">En el ejemplo `Catch` se incluyen instrucciones para varios tipos de excepciones, ordenadas de la más específica a la más general.</span><span class="sxs-lookup"><span data-stu-id="c9a13-240">The example includes `Catch` statements for several types of exceptions, ordered from the most specific to the most general.</span></span>

[!code-vb[VbVbalrStatements#91](~/samples/snippets/visualbasic/VS_Snippets_VBCSharp/VbVbalrStatements/VB/Class1.vb#91)]

### <a name="the-catch-when-statement"></a><span data-ttu-id="c9a13-241">La instrucción Catch When</span><span class="sxs-lookup"><span data-stu-id="c9a13-241">The Catch When statement</span></span>

<span data-ttu-id="c9a13-242">En el ejemplo siguiente se muestra cómo usar una `Catch When` instrucción para filtrar por una expresión condicional.</span><span class="sxs-lookup"><span data-stu-id="c9a13-242">The following example shows how to use a `Catch When` statement to filter on a conditional expression.</span></span> <span data-ttu-id="c9a13-243">Si la expresión condicional se evalúa como `True` , se ejecuta el código del `Catch` bloque.</span><span class="sxs-lookup"><span data-stu-id="c9a13-243">If the conditional expression evaluates to `True`, the code in the `Catch` block runs.</span></span>

[!code-vb[VbVbalrStatements#92](~/samples/snippets/visualbasic/VS_Snippets_VBCSharp/VbVbalrStatements/VB/Class1.vb#92)]

### <a name="nested-try-statements"></a><span data-ttu-id="c9a13-244">Instrucciones try anidadas</span><span class="sxs-lookup"><span data-stu-id="c9a13-244">Nested Try statements</span></span>

<span data-ttu-id="c9a13-245">El ejemplo siguiente tiene una `Try…Catch` instrucción que se encuentra en un `Try` bloque.</span><span class="sxs-lookup"><span data-stu-id="c9a13-245">The following example has a `Try…Catch` statement that is contained in a `Try` block.</span></span> <span data-ttu-id="c9a13-246">El `Catch` bloque interno produce una excepción que tiene su `InnerException` propiedad establecida en la excepción original.</span><span class="sxs-lookup"><span data-stu-id="c9a13-246">The inner `Catch` block throws an exception that has its `InnerException` property set to the original exception.</span></span> <span data-ttu-id="c9a13-247">El `Catch` bloque externo notifica su propia excepción y la excepción interna.</span><span class="sxs-lookup"><span data-stu-id="c9a13-247">The outer `Catch` block reports its own exception and the inner exception.</span></span>

[!code-vb[VbVbalrStatements#93](~/samples/snippets/visualbasic/VS_Snippets_VBCSharp/VbVbalrStatements/VB/Class1.vb#93)]

### <a name="exception-handling-for-async-methods"></a><span data-ttu-id="c9a13-248">Control de excepciones para métodos asincrónicos</span><span class="sxs-lookup"><span data-stu-id="c9a13-248">Exception handling for async methods</span></span>

<span data-ttu-id="c9a13-249">En el ejemplo siguiente se muestra el control de excepciones de los métodos asincrónicos.</span><span class="sxs-lookup"><span data-stu-id="c9a13-249">The following example illustrates exception handling for async methods.</span></span> <span data-ttu-id="c9a13-250">Para detectar una excepción que se aplica a una tarea asincrónica, la `Await` expresión se encuentra en un `Try` bloque del llamador y la excepción se captura en el `Catch` bloque.</span><span class="sxs-lookup"><span data-stu-id="c9a13-250">To catch an exception that applies to an async task, the `Await` expression is in a `Try` block of the caller, and the exception is caught in the `Catch` block.</span></span>

<span data-ttu-id="c9a13-251">Quite la marca de comentario de la línea `Throw New Exception` en el ejemplo para demostrar el control de excepciones.</span><span class="sxs-lookup"><span data-stu-id="c9a13-251">Uncomment the `Throw New Exception` line in the example to demonstrate exception handling.</span></span> <span data-ttu-id="c9a13-252">La excepción se detecta en el `Catch` bloque, la propiedad de la tarea `IsFaulted` se establece en `True` y la propiedad de la tarea `Exception.InnerException` se establece en la excepción.</span><span class="sxs-lookup"><span data-stu-id="c9a13-252">The exception is caught in the `Catch` block, the task's `IsFaulted` property is set to `True`, and the task's `Exception.InnerException` property is set to the exception.</span></span>

<span data-ttu-id="c9a13-253">Quite la marca de comentario de la línea `Throw New OperationCancelledException` para ver lo que pasa cuando se cancela un proceso asincrónico.</span><span class="sxs-lookup"><span data-stu-id="c9a13-253">Uncomment the `Throw New OperationCancelledException` line to demonstrate what happens when you cancel an asynchronous process.</span></span> <span data-ttu-id="c9a13-254">La excepción se detecta en el `Catch` bloque y la propiedad de la tarea `IsCanceled` se establece en `True` .</span><span class="sxs-lookup"><span data-stu-id="c9a13-254">The exception is caught in the `Catch` block, and the task's `IsCanceled` property is set to `True`.</span></span> <span data-ttu-id="c9a13-255">Sin embargo, en algunas condiciones que no se aplican a este ejemplo, `IsFaulted` se establece en `True` y `IsCanceled` se establece en `False` .</span><span class="sxs-lookup"><span data-stu-id="c9a13-255">However, under some conditions that don't apply to this example, `IsFaulted` is set to `True` and `IsCanceled` is set to `False`.</span></span>

[!code-vb[csAsyncExceptions#1](~/samples/snippets/visualbasic/VS_Snippets_VBCSharp/csasyncexceptions/vb/class1.vb#1)]

### <a name="handling-multiple-exceptions-in-async-methods"></a><span data-ttu-id="c9a13-256">Controlar varias excepciones en métodos asincrónicos</span><span class="sxs-lookup"><span data-stu-id="c9a13-256">Handling multiple exceptions in async methods</span></span>

<span data-ttu-id="c9a13-257">En el ejemplo siguiente se muestra el control de excepciones en el que varias tareas pueden producir varias excepciones.</span><span class="sxs-lookup"><span data-stu-id="c9a13-257">The following example illustrates exception handling where multiple tasks can result in multiple exceptions.</span></span> <span data-ttu-id="c9a13-258">El `Try` bloque tiene la `Await` expresión de la tarea que <xref:System.Threading.Tasks.Task.WhenAll%2A?displayProperty=nameWithType> devolvió.</span><span class="sxs-lookup"><span data-stu-id="c9a13-258">The `Try` block has the `Await` expression for the task that <xref:System.Threading.Tasks.Task.WhenAll%2A?displayProperty=nameWithType> returned.</span></span> <span data-ttu-id="c9a13-259">La tarea se completa cuando se completan las tres tareas a las que <xref:System.Threading.Tasks.Task.WhenAll%2A?displayProperty=nameWithType> se aplica.</span><span class="sxs-lookup"><span data-stu-id="c9a13-259">The task is complete when the three tasks to which <xref:System.Threading.Tasks.Task.WhenAll%2A?displayProperty=nameWithType> is applied are complete.</span></span>

<span data-ttu-id="c9a13-260">Cada una de las tres tareas produce una excepción.</span><span class="sxs-lookup"><span data-stu-id="c9a13-260">Each of the three tasks causes an exception.</span></span> <span data-ttu-id="c9a13-261">El `Catch` bloque recorre en iteración las excepciones, que se encuentran en la `Exception.InnerExceptions` propiedad de la tarea que `Task.WhenAll` devolvió.</span><span class="sxs-lookup"><span data-stu-id="c9a13-261">The `Catch` block iterates through the exceptions, which are found in the `Exception.InnerExceptions` property of the task that `Task.WhenAll` returned.</span></span>

[!code-vb[csAsyncExceptions#3](~/samples/snippets/visualbasic/VS_Snippets_VBCSharp/csasyncexceptions/vb/class1.vb#3)]

## <a name="see-also"></a><span data-ttu-id="c9a13-262">Consulte también</span><span class="sxs-lookup"><span data-stu-id="c9a13-262">See also</span></span>

- <xref:Microsoft.VisualBasic.Information.Err%2A>
- <xref:System.Exception>
- [<span data-ttu-id="c9a13-263">Instrucción Exit</span><span class="sxs-lookup"><span data-stu-id="c9a13-263">Exit Statement</span></span>](exit-statement.md)
- [<span data-ttu-id="c9a13-264">Instrucción On Error</span><span class="sxs-lookup"><span data-stu-id="c9a13-264">On Error Statement</span></span>](on-error-statement.md)
- [<span data-ttu-id="c9a13-265">Procedimientos recomendados para usar fragmentos de código</span><span class="sxs-lookup"><span data-stu-id="c9a13-265">Best Practices for Using Code Snippets</span></span>](/visualstudio/ide/best-practices-for-using-code-snippets)
- [<span data-ttu-id="c9a13-266">Control de excepciones</span><span class="sxs-lookup"><span data-stu-id="c9a13-266">Exception Handling</span></span>](../../../standard/parallel-programming/exception-handling-task-parallel-library.md)
- [<span data-ttu-id="c9a13-267">Throw (instrucción)</span><span class="sxs-lookup"><span data-stu-id="c9a13-267">Throw Statement</span></span>](throw-statement.md)
