---
title: 'Usar excepciones: Guía de programación de C#'
ms.date: 07/20/2015
helpviewer_keywords:
- exception handling [C#], about exception handling
- exceptions [C#], about exceptions
ms.assetid: 71472c62-320a-470a-97d2-67995180389d
ms.openlocfilehash: a00259dfd5634ad9b9c951c3cd76da97afe5077d
ms.sourcegitcommit: a241301495a84cc8c64fe972330d16edd619868b
ms.translationtype: HT
ms.contentlocale: es-ES
ms.lasthandoff: 06/01/2020
ms.locfileid: "84241700"
---
# <a name="use-exceptions-c-programming-guide"></a><span data-ttu-id="c86a2-102">Uso de excepciones (guía de programación de C#)</span><span class="sxs-lookup"><span data-stu-id="c86a2-102">Use exceptions (C# programming guide)</span></span>

<span data-ttu-id="c86a2-103">En C#, los errores del programa en tiempo de ejecución se propagan a través del programa mediante un mecanismo denominado excepciones.</span><span class="sxs-lookup"><span data-stu-id="c86a2-103">In C#, errors in the program at run time are propagated through the program by using a mechanism called exceptions.</span></span> <span data-ttu-id="c86a2-104">Las excepciones las inicia el código que encuentra un error y las detecta el código que puede corregir dicho error.</span><span class="sxs-lookup"><span data-stu-id="c86a2-104">Exceptions are thrown by code that encounters an error and caught by code that can correct the error.</span></span> <span data-ttu-id="c86a2-105">El entorno de ejecución .NET o el código de un programa pueden producir excepciones.</span><span class="sxs-lookup"><span data-stu-id="c86a2-105">Exceptions can be thrown by the .NET runtime or by code in a program.</span></span> <span data-ttu-id="c86a2-106">Una vez iniciada, una excepción se propaga hasta la pila de llamadas hasta que encuentra una instrucción `catch` para la excepción.</span><span class="sxs-lookup"><span data-stu-id="c86a2-106">Once an exception is thrown, it propagates up the call stack until a `catch` statement for the exception is found.</span></span> <span data-ttu-id="c86a2-107">Las excepciones no detectadas se controlan mediante un controlador de excepciones que ofrece el sistema y muestra un cuadro de diálogo.</span><span class="sxs-lookup"><span data-stu-id="c86a2-107">Uncaught exceptions are handled by a generic exception handler provided by the system that displays a dialog box.</span></span>  
  
 <span data-ttu-id="c86a2-108">Las excepciones están representadas por clases derivadas de <xref:System.Exception>.</span><span class="sxs-lookup"><span data-stu-id="c86a2-108">Exceptions are represented by classes derived from <xref:System.Exception>.</span></span> <span data-ttu-id="c86a2-109">Esta clase identifica el tipo de excepción y contiene propiedades que tienen los detalles sobre la excepción.</span><span class="sxs-lookup"><span data-stu-id="c86a2-109">This class identifies the type of exception and contains properties that have details about the exception.</span></span> <span data-ttu-id="c86a2-110">Iniciar una excepción implica crear una instancia de una clase derivada de excepción, configurar opcionalmente las propiedades de la excepción y luego producir el objeto con la palabra clave `throw`.</span><span class="sxs-lookup"><span data-stu-id="c86a2-110">Throwing an exception involves creating an instance of an exception-derived class, optionally configuring properties of the exception, and then throwing the object by using the `throw` keyword.</span></span> <span data-ttu-id="c86a2-111">Por ejemplo:</span><span class="sxs-lookup"><span data-stu-id="c86a2-111">For example:</span></span>  
  
 [!code-csharp[csProgGuideExceptions#1](~/samples/snippets/csharp/VS_Snippets_VBCSharp/csProgGuideExceptions/CS/Exceptions.cs#1)]  
  
 <span data-ttu-id="c86a2-112">Cuando se inicia una excepción, el entorno runtime comprueba la instrucción actual para ver si se encuentra dentro de un bloque `try`.</span><span class="sxs-lookup"><span data-stu-id="c86a2-112">After an exception is thrown, the runtime checks the current statement to see whether it is within a `try` block.</span></span> <span data-ttu-id="c86a2-113">Si es así, se comprueban los bloques `catch` asociados al bloque `try` para ver si pueden detectar la excepción.</span><span class="sxs-lookup"><span data-stu-id="c86a2-113">If it is, any `catch` blocks associated with the `try` block are checked to see whether they can catch the exception.</span></span> <span data-ttu-id="c86a2-114">Los bloques `Catch` suelen especificar tipos de excepción; si el tipo del bloque `catch` es el mismo de la excepción, o una clase base de la excepción, el bloque `catch` puede controlar el método.</span><span class="sxs-lookup"><span data-stu-id="c86a2-114">`Catch` blocks typically specify exception types; if the type of the `catch` block is the same type as the exception, or a base class of the exception, the `catch` block can handle the method.</span></span> <span data-ttu-id="c86a2-115">Por ejemplo:</span><span class="sxs-lookup"><span data-stu-id="c86a2-115">For example:</span></span>  
  
 [!code-csharp[csProgGuideExceptions#2](~/samples/snippets/csharp/VS_Snippets_VBCSharp/csProgGuideExceptions/CS/Exceptions.cs#2)]  
  
 <span data-ttu-id="c86a2-116">Si la instrucción que inicia una excepción no está en un bloque `try` o si el bloque `try` que la encierra no tiene un bloque `catch` coincidente, el entorno runtime busca una instrucción `try` y bloques `catch` en el método de llamada.</span><span class="sxs-lookup"><span data-stu-id="c86a2-116">If the statement that throws an exception is not within a `try` block or if the `try` block that encloses it has no matching `catch` block, the runtime checks the calling method for a `try` statement and `catch` blocks.</span></span> <span data-ttu-id="c86a2-117">El entorno runtime sigue hasta la pila de llamadas para buscar un bloque `catch` compatible.</span><span class="sxs-lookup"><span data-stu-id="c86a2-117">The runtime continues up the calling stack, searching for a compatible `catch` block.</span></span> <span data-ttu-id="c86a2-118">Después de encontrar el bloque `catch` y ejecutarlo, el control pasa a la siguiente instrucción después de dicho bloque `catch`.</span><span class="sxs-lookup"><span data-stu-id="c86a2-118">After the `catch` block is found and executed, control is passed to the next statement after that `catch` block.</span></span>  
  
 <span data-ttu-id="c86a2-119">Una instrucción `try` puede contener más de un bloque `catch`.</span><span class="sxs-lookup"><span data-stu-id="c86a2-119">A `try` statement can contain more than one `catch` block.</span></span> <span data-ttu-id="c86a2-120">Se ejecuta la primera instrucción `catch` que pueda controlar la excepción; las instrucciones `catch` siguientes se omiten, aunque sean compatibles.</span><span class="sxs-lookup"><span data-stu-id="c86a2-120">The first `catch` statement that can handle the exception is executed; any following `catch` statements, even if they are compatible, are ignored.</span></span> <span data-ttu-id="c86a2-121">Por consiguiente, los bloques catch deben ordenarse siempre de más específico (o más derivado) a menos específico.</span><span class="sxs-lookup"><span data-stu-id="c86a2-121">Therefore, catch blocks should always be ordered from most specific (or most-derived) to least specific.</span></span> <span data-ttu-id="c86a2-122">Por ejemplo:</span><span class="sxs-lookup"><span data-stu-id="c86a2-122">For example:</span></span>  
  
 [!code-csharp[csProgGuideExceptions#3](~/samples/snippets/csharp/VS_Snippets_VBCSharp/csProgGuideExceptions/CS/Exceptions.cs#3)]  
  
 <span data-ttu-id="c86a2-123">Para que el bloque `catch` se ejecute, el entorno runtime busca bloques `finally`.</span><span class="sxs-lookup"><span data-stu-id="c86a2-123">Before the `catch` block is executed, the runtime checks for `finally` blocks.</span></span> <span data-ttu-id="c86a2-124">Los bloques `Finally` permiten al programador limpiar cualquier estado ambiguo que pudiera haber quedado tras la anulación de un bloque `try` o liberar los recursos externos (como identificadores de gráficos, conexiones de base de datos o flujos de archivos) sin tener que esperar a que el recolector de elementos no utilizados del entorno runtime finalice los objetos.</span><span class="sxs-lookup"><span data-stu-id="c86a2-124">`Finally` blocks enable the programmer to clean up any ambiguous state that could be left over from an aborted `try` block, or to release any external resources (such as graphics handles, database connections or file streams) without waiting for the garbage collector in the runtime to finalize the objects.</span></span> <span data-ttu-id="c86a2-125">Por ejemplo:</span><span class="sxs-lookup"><span data-stu-id="c86a2-125">For example:</span></span>  
  
 [!code-csharp[csProgGuideExceptions#4](~/samples/snippets/csharp/VS_Snippets_VBCSharp/csProgGuideExceptions/CS/Exceptions.cs#4)]  
  
 <span data-ttu-id="c86a2-126">Si `WriteByte()` ha iniciado una excepción, el código del segundo bloque `try` que intente reabrir el archivo generaría un error si no se llama a `file.Close()` y el archivo permanecería bloqueado.</span><span class="sxs-lookup"><span data-stu-id="c86a2-126">If `WriteByte()` threw an exception, the code in the second `try` block that tries to reopen the file would fail if `file.Close()` is not called, and the file would remain locked.</span></span> <span data-ttu-id="c86a2-127">Como los bloques `finally` se ejecutan aunque se inicie una excepción, el bloque `finally` del ejemplo anterior permite que el archivo se cierre correctamente y ayuda a evitar un error.</span><span class="sxs-lookup"><span data-stu-id="c86a2-127">Because `finally` blocks are executed even if an exception is thrown, the `finally` block in the previous example allows for the file to be closed correctly and helps avoid an error.</span></span>  
  
 <span data-ttu-id="c86a2-128">Si no se encuentra ningún bloque `catch` compatible en la pila de llamadas después de iniciar una excepción, sucede una de estas tres acciones:</span><span class="sxs-lookup"><span data-stu-id="c86a2-128">If no compatible `catch` block is found on the call stack after an exception is thrown, one of three things occurs:</span></span>  
  
- <span data-ttu-id="c86a2-129">Si la excepción se encuentra en un finalizador, este se anula y, si procede, se llama al finalizador base.</span><span class="sxs-lookup"><span data-stu-id="c86a2-129">If the exception is within a finalizer, the finalizer is aborted and the base finalizer, if any, is called.</span></span>  
  
- <span data-ttu-id="c86a2-130">Si la pila de llamadas contiene un constructor estático o un inicializador de campo estático, se inicia una excepción <xref:System.TypeInitializationException>, y la excepción original se asigna a la propiedad <xref:System.Exception.InnerException%2A> de la nueva excepción.</span><span class="sxs-lookup"><span data-stu-id="c86a2-130">If the call stack contains a static constructor, or a static field initializer, a <xref:System.TypeInitializationException> is thrown, with the original exception assigned to the <xref:System.Exception.InnerException%2A> property of the new exception.</span></span>  
  
- <span data-ttu-id="c86a2-131">Si se llega al comienzo del subproceso, este finaliza.</span><span class="sxs-lookup"><span data-stu-id="c86a2-131">If the start of the thread is reached, the thread is terminated.</span></span>  
  
## <a name="see-also"></a><span data-ttu-id="c86a2-132">Vea también</span><span class="sxs-lookup"><span data-stu-id="c86a2-132">See also</span></span>

- [<span data-ttu-id="c86a2-133">Guía de programación de C#</span><span class="sxs-lookup"><span data-stu-id="c86a2-133">C# Programming Guide</span></span>](../index.md)
- [<span data-ttu-id="c86a2-134">Excepciones y control de excepciones</span><span class="sxs-lookup"><span data-stu-id="c86a2-134">Exceptions and Exception Handling</span></span>](./index.md)
